<?xml version="1.0" ?>
<robot name="AROBO7" xmlns:xacro="http://www.ros.org/wiki/xacro">

<!-- Old ROS1 sub args from python script, dont use
<xacro:include filename="$(find AROBO7)/description/materials.xacro" />
<xacro:include filename="$(find AROBO7)/description/AROBO7.trans" />
<xacro:include filename="$(find AROBO7)/description/AROBO7.gazebo" />
-->

<xacro:arg name="materials_file" default="materials.xacro"/>
<xacro:arg name="trans_file" default="AROBO7.trans"/>
<xacro:arg name="gazebo_file" default="AROBO7.gazebo"/>

<xacro:include filename="$(arg materials_file)" />
<xacro:include filename="$(arg trans_file)" />
<xacro:include filename="$(arg gazebo_file)" />

<link name="base_link">
  <inertial>
    <origin xyz="0.13096721223027635 0.20058924182261065 0.2752839368254627" rpy="0 0 0"/>
    <mass value="3.2922550379120885"/>
    <inertia ixx="0.011321" iyy="0.016138" izz="0.021277" ixy="-4e-06" iyz="-0.003328" ixz="-1e-06"/>
  </inertial>
  <visual>
    <origin xyz="0 0 0" rpy="0 0 0"/>
    <geometry>
      <mesh filename="package://AROBO7/description/meshes/base_link.stl" scale="0.001 0.001 0.001"/>
    </geometry>
    <material name="darkgrey"/>
  </visual>
  <collision>
    <origin xyz="0 0 0" rpy="0 0 0"/>
    <geometry>
      <mesh filename="package://AROBO7/description/meshes/base_link.stl" scale="0.001 0.001 0.001"/>
    </geometry>
  </collision>
</link>

<link name="drive_side_plate_v42_1_1">
  <inertial>
    <origin xyz="-0.012023150431202044 -0.09333406272773866 0.0566326473522496" rpy="0 0 0"/>
    <mass value="5.326807202481426"/>
    <inertia ixx="0.052355" iyy="0.00619" izz="0.047069" ixy="6.5e-05" iyz="-0.000154" ixz="0.000596"/>
  </inertial>
  <visual>
    <origin xyz="-0.020984 -0.18342 -0.253475" rpy="0 0 0"/>
    <geometry>
      <mesh filename="package://AROBO7/description/meshes/drive_side_plate_v42_1_1.stl" scale="0.001 0.001 0.001"/>
    </geometry>
    <material name="olive"/>
  </visual>
  <collision>
    <origin xyz="-0.020984 -0.18342 -0.253475" rpy="0 0 0"/>
    <geometry>
      <mesh filename="package://AROBO7/description/meshes/drive_side_plate_v42_1_1.stl" scale="0.001 0.001 0.001"/>
    </geometry>
  </collision>
</link>

<link name="sprocket_new_v28_1_1">
  <inertial>
    <origin xyz="-0.010830985333184509 2.382412599234718e-06 -3.4590502762665842e-06" rpy="0 0 0"/>
    <mass value="0.5034568043679143"/>
    <inertia ixx="0.000505" iyy="0.000257" izz="0.000257" ixy="-0.0" iyz="-0.0" ixz="0.0"/>
  </inertial>
  <visual>
    <origin xyz="-0.002484 0.028711 -0.290475" rpy="0 0 0"/>
    <geometry>
      <mesh filename="package://AROBO7/description/meshes/sprocket_new_v28_1_1.stl" scale="0.001 0.001 0.001"/>
    </geometry>
    <material name="darkgrey"/>
  </visual>
  <collision>
    <origin xyz="-0.002484 0.028711 -0.290475" rpy="0 0 0"/>
    <geometry>
      <mesh filename="package://AROBO7/description/meshes/sprocket_new_v28_1_1.stl" scale="0.001 0.001 0.001"/>
    </geometry>
  </collision>
</link>

<link name="sprocket_new_v28_2_1">
  <inertial>
    <origin xyz="-0.01083098533318511 2.3777572445426998e-06 -3.459050277654363e-06" rpy="0 0 0"/>
    <mass value="0.5034568043679143"/>
    <inertia ixx="0.000505" iyy="0.000257" izz="0.000257" ixy="-0.0" iyz="-0.0" ixz="0.0"/>
  </inertial>
  <visual>
    <origin xyz="-0.002484 -0.213419 -0.290475" rpy="0 0 0"/>
    <geometry>
      <mesh filename="package://AROBO7/description/meshes/sprocket_new_v28_2_1.stl" scale="0.001 0.001 0.001"/>
    </geometry>
    <material name="darkgrey"/>
  </visual>
  <collision>
    <origin xyz="-0.002484 -0.213419 -0.290475" rpy="0 0 0"/>
    <geometry>
      <mesh filename="package://AROBO7/description/meshes/sprocket_new_v28_2_1.stl" scale="0.001 0.001 0.001"/>
    </geometry>
  </collision>
</link>

<link name="drive_side_plate_v42_Mirror__1_1">
  <inertial>
    <origin xyz="0.012022509624825789 -0.14949706270783558 0.04579464742293965" rpy="0 0 0"/>
    <mass value="5.326807201855023"/>
    <inertia ixx="0.052355" iyy="0.00619" izz="0.047069" ixy="-6.5e-05" iyz="-0.000154" ixz="-0.000596"/>
  </inertial>
  <visual>
    <origin xyz="-0.240984 -0.239583 -0.264313" rpy="0 0 0"/>
    <geometry>
      <mesh filename="package://AROBO7/description/meshes/drive_side_plate_v42_Mirror__1_1.stl" scale="0.001 0.001 0.001"/>
    </geometry>
    <material name="olive"/>
  </visual>
  <collision>
    <origin xyz="-0.240984 -0.239583 -0.264313" rpy="0 0 0"/>
    <geometry>
      <mesh filename="package://AROBO7/description/meshes/drive_side_plate_v42_Mirror__1_1.stl" scale="0.001 0.001 0.001"/>
    </geometry>
  </collision>
</link>

<link name="sprocket_new_v28_4_1">
  <inertial>
    <origin xyz="0.010830340021314333 2.377757242044698e-06 4.442076691701935e-06" rpy="0 0 0"/>
    <mass value="0.5034568043679111"/>
    <inertia ixx="0.000505" iyy="0.000257" izz="0.000257" ixy="0.0" iyz="0.0" ixz="0.0"/>
  </inertial>
  <visual>
    <origin xyz="-0.259484 -0.213419 -0.290475" rpy="0 0 0"/>
    <geometry>
      <mesh filename="package://AROBO7/description/meshes/sprocket_new_v28_4_1.stl" scale="0.001 0.001 0.001"/>
    </geometry>
    <material name="darkgrey"/>
  </visual>
  <collision>
    <origin xyz="-0.259484 -0.213419 -0.290475" rpy="0 0 0"/>
    <geometry>
      <mesh filename="package://AROBO7/description/meshes/sprocket_new_v28_4_1.stl" scale="0.001 0.001 0.001"/>
    </geometry>
  </collision>
</link>

<link name="sprocket_new_v28_3_1">
  <inertial>
    <origin xyz="0.010830340021315554 2.3824125974930555e-06 4.4420766926456245e-06" rpy="0 0 0"/>
    <mass value="0.5034568043679192"/>
    <inertia ixx="0.000505" iyy="0.000257" izz="0.000257" ixy="0.0" iyz="0.0" ixz="0.0"/>
  </inertial>
  <visual>
    <origin xyz="-0.259484 0.028711 -0.290475" rpy="0 0 0"/>
    <geometry>
      <mesh filename="package://AROBO7/description/meshes/sprocket_new_v28_3_1.stl" scale="0.001 0.001 0.001"/>
    </geometry>
    <material name="darkgrey"/>
  </visual>
  <collision>
    <origin xyz="-0.259484 0.028711 -0.290475" rpy="0 0 0"/>
    <geometry>
      <mesh filename="package://AROBO7/description/meshes/sprocket_new_v28_3_1.stl" scale="0.001 0.001 0.001"/>
    </geometry>
  </collision>
</link>

<link name="lower_chassis_front_v6_1_1">
  <inertial>
    <origin xyz="-0.06752027497646867 -0.10569116129549466 0.026875055875444365" rpy="0 0 0"/>
    <mass value="3.0761672555380986"/>
    <inertia ixx="0.010661" iyy="0.014341" izz="0.021129" ixy="2e-06" iyz="0.003357" ixz="-1e-06"/>
  </inertial>
  <visual>
    <origin xyz="-0.198484 -0.101605 -0.253475" rpy="0 0 0"/>
    <geometry>
      <mesh filename="package://AROBO7/description/meshes/lower_chassis_front_v6_1_1.stl" scale="0.001 0.001 0.001"/>
    </geometry>
    <material name="darkgrey"/>
  </visual>
  <collision>
    <origin xyz="-0.198484 -0.101605 -0.253475" rpy="0 0 0"/>
    <geometry>
      <mesh filename="package://AROBO7/description/meshes/lower_chassis_front_v6_1_1.stl" scale="0.001 0.001 0.001"/>
    </geometry>
  </collision>
</link>

<link name="upper_chassis_back_v10_1_1">
  <inertial>
    <origin xyz="0.02069821423371679 -0.04681860405746971 0.053343397365645306" rpy="0 0 0"/>
    <mass value="3.8016594283307508"/>
    <inertia ixx="0.008862" iyy="0.026179" izz="0.030198" ixy="0.00016" iyz="0.001827" ixz="-0.000247"/>
  </inertial>
  <visual>
    <origin xyz="-0.110984 -0.23642 -0.338705" rpy="0 0 0"/>
    <geometry>
      <mesh filename="package://AROBO7/description/meshes/upper_chassis_back_v10_1_1.stl" scale="0.001 0.001 0.001"/>
    </geometry>
    <material name="darkgrey"/>
  </visual>
  <collision>
    <origin xyz="-0.110984 -0.23642 -0.338705" rpy="0 0 0"/>
    <geometry>
      <mesh filename="package://AROBO7/description/meshes/upper_chassis_back_v10_1_1.stl" scale="0.001 0.001 0.001"/>
    </geometry>
  </collision>
</link>

<link name="upper_chassis_front_v12_1_1">
  <inertial>
    <origin xyz="-0.00011191810875865738 -0.0686938821678975 -0.04016009009950566" rpy="0 0 0"/>
    <mass value="2.368628323291725"/>
    <inertia ixx="0.00684" iyy="0.018257" izz="0.022292" ixy="4.7e-05" iyz="-0.002351" ixz="2e-05"/>
  </inertial>
  <visual>
    <origin xyz="-0.130884 -0.105388 -0.422426" rpy="0 0 0"/>
    <geometry>
      <mesh filename="package://AROBO7/description/meshes/upper_chassis_front_v12_1_1.stl" scale="0.001 0.001 0.001"/>
    </geometry>
    <material name="darkgrey"/>
  </visual>
  <collision>
    <origin xyz="-0.130884 -0.105388 -0.422426" rpy="0 0 0"/>
    <geometry>
      <mesh filename="package://AROBO7/description/meshes/upper_chassis_front_v12_1_1.stl" scale="0.001 0.001 0.001"/>
    </geometry>
  </collision>
</link>

<link name="RpLidar_Case_Top_High_v6_1_1">
  <inertial>
    <origin xyz="-0.06417189427357384 -3.830630171119953e-07 0.0025803158490367295" rpy="0 0 0"/>
    <mass value="0.0845829809011377"/>
    <inertia ixx="5.7e-05" iyy="0.000128" izz="0.000185" ixy="-0.0" iyz="-0.0" ixz="0.0"/>
  </inertial>
  <visual>
    <origin xyz="-0.174394 -0.156967 -0.432527" rpy="0 0 0"/>
    <geometry>
      <mesh filename="package://AROBO7/description/meshes/RpLidar_Case_Top_High_v6_1_1.stl" scale="0.001 0.001 0.001"/>
    </geometry>
    <material name="olive"/>
  </visual>
  <collision>
    <origin xyz="-0.174394 -0.156967 -0.432527" rpy="0 0 0"/>
    <geometry>
      <mesh filename="package://AROBO7/description/meshes/RpLidar_Case_Top_High_v6_1_1.stl" scale="0.001 0.001 0.001"/>
    </geometry>
  </collision>
</link>

<link name="rplidar_sensor_v1_1_1">
  <inertial>
    <origin xyz="-3.677012131997337e-07 -3.7389566448498e-07 0.00999977147532144" rpy="0 0 0"/>
    <mass value="0.675231933814029"/>
    <inertia ixx="0.000254" iyy="0.000254" izz="0.000462" ixy="-0.0" iyz="-0.0" ixz="-0.0"/>
  </inertial>
  <visual>
    <origin xyz="-0.130894 -0.156967 -0.436527" rpy="0 0 0"/>
    <geometry>
      <mesh filename="package://AROBO7/description/meshes/rplidar_sensor_v1_1_1.stl" scale="0.001 0.001 0.001"/>
    </geometry>
    <material name="black"/>
  </visual>
  <collision>
    <origin xyz="-0.130894 -0.156967 -0.436527" rpy="0 0 0"/>
    <geometry>
      <mesh filename="package://AROBO7/description/meshes/rplidar_sensor_v1_1_1.stl" scale="0.001 0.001 0.001"/>
    </geometry>
  </collision>
</link>

<link name="RpLidar_Case_Bot_v8_1_1">
  <inertial>
    <origin xyz="-0.05411714563331993 -0.034343073172691474 -0.013957332277793222" rpy="0 0 0"/>
    <mass value="0.4471773333473896"/>
    <inertia ixx="0.000464" iyy="0.000828" izz="0.001112" ixy="0.0" iyz="-0.0" ixz="0.0"/>
  </inertial>
  <visual>
    <origin xyz="-0.173633 -0.19131 -0.418526" rpy="0 0 0"/>
    <geometry>
      <mesh filename="package://AROBO7/description/meshes/RpLidar_Case_Bot_v8_1_1.stl" scale="0.001 0.001 0.001"/>
    </geometry>
    <material name="olive"/>
  </visual>
  <collision>
    <origin xyz="-0.173633 -0.19131 -0.418526" rpy="0 0 0"/>
    <geometry>
      <mesh filename="package://AROBO7/description/meshes/RpLidar_Case_Bot_v8_1_1.stl" scale="0.001 0.001 0.001"/>
    </geometry>
  </collision>
</link>

<link name="IPITSBIT_Touchscreen_7in_v4_1_1">
  <inertial>
    <origin xyz="0.07744240382982455 -0.044640388141649646 -0.012662220006309233" rpy="0 0 0"/>
    <mass value="1.0746135799107448"/>
    <inertia ixx="0.000975" iyy="0.00261" izz="0.003217" ixy="3e-06" iyz="-0.000373" ixz="1e-06"/>
  </inertial>
  <visual>
    <origin xyz="-0.053384 -0.037674 -0.383372" rpy="0 0 0"/>
    <geometry>
      <mesh filename="package://AROBO7/description/meshes/IPITSBIT_Touchscreen_7in_v4_1_1.stl" scale="0.001 0.001 0.001"/>
    </geometry>
    <material name="black"/>
  </visual>
  <collision>
    <origin xyz="-0.053384 -0.037674 -0.383372" rpy="0 0 0"/>
    <geometry>
      <mesh filename="package://AROBO7/description/meshes/IPITSBIT_Touchscreen_7in_v4_1_1.stl" scale="0.001 0.001 0.001"/>
    </geometry>
  </collision>
</link>

<link name="camera_back_2">
  <inertial>
    <origin xyz="0.015270203785861136 0.0004686192161018968 0.026827273506477456" rpy="0 0 0"/>
    <mass value="0.0414113473956684"/>
    <inertia ixx="8e-06" iyy="1.3e-05" izz="6e-06" ixy="0.0" iyz="0.0" ixz="-0.0"/>
  </inertial>
  <visual>
    <origin xyz="-0.115484 -0.055947 -0.390489" rpy="0 0 0"/>
    <geometry>
      <mesh filename="package://AROBO7/description/meshes/camera_back_2.stl" scale="0.001 0.001 0.001"/>
    </geometry>
    <material name="olive"/>
  </visual>
  <collision>
    <origin xyz="-0.115484 -0.055947 -0.390489" rpy="0 0 0"/>
    <geometry>
      <mesh filename="package://AROBO7/description/meshes/camera_back_2.stl" scale="0.001 0.001 0.001"/>
    </geometry>
  </collision>
</link>

<link name="camera_front_v7_1_1">
  <inertial>
    <origin xyz="-0.016513588197264645 -0.003812104733532551 -0.009160087315544907" rpy="0 0 0"/>
    <mass value="0.030275096674156586"/>
    <inertia ixx="3e-06" iyy="6e-06" izz="4e-06" ixy="0.0" iyz="0.0" ixz="-0.0"/>
  </inertial>
  <visual>
    <origin xyz="-0.147484 -0.054116 -0.429139" rpy="0 0 0"/>
    <geometry>
      <mesh filename="package://AROBO7/description/meshes/camera_front_v7_1_1.stl" scale="0.001 0.001 0.001"/>
    </geometry>
    <material name="olive"/>
  </visual>
  <collision>
    <origin xyz="-0.147484 -0.054116 -0.429139" rpy="0 0 0"/>
    <geometry>
      <mesh filename="package://AROBO7/description/meshes/camera_front_v7_1_1.stl" scale="0.001 0.001 0.001"/>
    </geometry>
  </collision>
</link>

<joint name="Rigid 1" type="fixed">
  <origin xyz="0.020984 0.18342 0.253475" rpy="0 0 0"/>
  <parent link="base_link"/>
  <child link="drive_side_plate_v42_1_1"/>
</joint>

<joint name="Rigid 2" type="fixed">
  <origin xyz="-0.0185 -0.212131 0.037" rpy="0 0 0"/>
  <parent link="drive_side_plate_v42_1_1"/>
  <child link="sprocket_new_v28_1_1"/>
</joint>

<joint name="right_drive" type="continuous">
  <origin xyz="-0.0185 0.029999 0.037" rpy="0 0 0"/>
  <parent link="drive_side_plate_v42_1_1"/>
  <child link="sprocket_new_v28_2_1"/>
  <axis xyz="1.0 -0.0 0.0"/>
</joint>

<joint name="Rigid 4" type="fixed">
  <origin xyz="0.240984 0.239583 0.264313" rpy="0 0 0"/>
  <parent link="base_link"/>
  <child link="drive_side_plate_v42_Mirror__1_1"/>
</joint>

<joint name="left_drive" type="continuous">
  <origin xyz="0.0185 -0.026164 0.026162" rpy="0 0 0"/>
  <parent link="drive_side_plate_v42_Mirror__1_1"/>
  <child link="sprocket_new_v28_4_1"/>
  <axis xyz="1.0 -0.0 0.0"/>
</joint>

<joint name="Rigid 6" type="fixed">
  <origin xyz="0.0185 -0.268294 0.026162" rpy="0 0 0"/>
  <parent link="drive_side_plate_v42_Mirror__1_1"/>
  <child link="sprocket_new_v28_3_1"/>
</joint>

<joint name="Rigid 7" type="fixed">
  <origin xyz="0.198484 0.101605 0.253475" rpy="0 0 0"/>
  <parent link="base_link"/>
  <child link="lower_chassis_front_v6_1_1"/>
</joint>

<joint name="Rigid 8" type="fixed">
  <origin xyz="0.110984 0.23642 0.338705" rpy="0 0 0"/>
  <parent link="base_link"/>
  <child link="upper_chassis_back_v10_1_1"/>
</joint>

<joint name="Rigid 9" type="fixed">
  <origin xyz="0.0199 -0.131032 0.083721" rpy="0 0 0"/>
  <parent link="upper_chassis_back_v10_1_1"/>
  <child link="upper_chassis_front_v12_1_1"/>
</joint>

<joint name="Rigid 10" type="fixed">
  <origin xyz="0.000761 -0.034343 0.014001" rpy="0 0 0"/>
  <parent link="RpLidar_Case_Bot_v8_1_1"/>
  <child link="RpLidar_Case_Top_High_v6_1_1"/>
</joint>

<joint name="Rigid 11" type="fixed">
  <origin xyz="-0.0435 0.0 0.004" rpy="0 0 0"/>
  <parent link="RpLidar_Case_Top_High_v6_1_1"/>
  <child link="rplidar_sensor_v1_1_1"/>
</joint>

<joint name="Rigid 12" type="fixed">
  <origin xyz="0.062649 -0.04511 0.079821" rpy="0 0 0"/>
  <parent link="upper_chassis_back_v10_1_1"/>
  <child link="RpLidar_Case_Bot_v8_1_1"/>
</joint>

<joint name="Rigid 13" type="fixed">
  <origin xyz="-0.0775 -0.067714 -0.039054" rpy="0 0 0"/>
  <parent link="upper_chassis_front_v12_1_1"/>
  <child link="IPITSBIT_Touchscreen_7in_v4_1_1"/>
</joint>

<joint name="Rigid 16" type="fixed">
  <origin xyz="-0.0154 -0.049441 -0.031937" rpy="0 0 0"/>
  <parent link="upper_chassis_front_v12_1_1"/>
  <child link="camera_back_2"/>
</joint>

<joint name="Rigid 17" type="fixed">
  <origin xyz="0.032 -0.001831 0.03865" rpy="0 0 0"/>
  <parent link="camera_back_2"/>
  <child link="camera_front_v7_1_1"/>
</joint>

</robot>
